<?xml version='1.0' encoding='utf-8'?>
<mujoco model="irb120_genesis_scene">
    <compiler angle="radian" meshdir="." />
    <option timestep="0.001" tolerance="1e-9" integrator="implicitfast" iterations="100" ls_iterations="100">
        <flag warmstart="enable" multiccd="enable" />
    </option>
    <visual>
        <global offwidth="1280" offheight="720" />
    </visual>
    <actuator>
        <position joint="joint_1" name="joint_1" kp="200" kv="100" ctrlrange="-2.87979 2.87979" forcerange="-20 20" />
        <position joint="joint_2" name="joint_2" kp="200" kv="100" ctrlrange="-1.91986 1.91986" forcerange="-20 20" />
        <position joint="joint_3" name="joint_3" kp="200" kv="100" ctrlrange="-1.22173 1.91986" forcerange="-20 20" />
        <position joint="joint_4" name="joint_4" kp="100" kv="50" ctrlrange="-2.79252 2.79252" forcerange="-10 10" />
        <position joint="joint_5" name="joint_5" kp="100" kv="50" ctrlrange="-2.09440 2.90440" forcerange="-10 10" />
        <position joint="joint_6" name="joint_6" kp="100" kv="50" ctrlrange="-3.14200 3.14200" forcerange="-10 10" />
    </actuator>
    <sensor>
        <force name="force_sensor" site="site:sensor" />
        <torque name="torque_sensor" site="site:sensor" />
    </sensor>
    <size njmax="500" nconmax="100" />
    <asset>
        <material name="MatObject" specular="0.75" shininess="0.1" reflectance="0.5" rgba="0.9 0.7 0.5 1" />
        <texture type="skybox" builtin="gradient" rgb1="0.45 0.6 0.807" rgb2="0.46 0.87 0.58" width="32" height="32" />
        <texture name="grid" type="2d" builtin="checker" rgb1=".1 .2 .3" rgb2=".2 .3 .4" width="300" height="300" />
        <material name="floor_mat" specular="0" shininess="0.5" reflectance="0" rgba="0.2 0.2 0.2 1" />
        <material name="table_mat" specular="0" shininess="0.5" reflectance="0" rgba="0.57 0.75 0.83 0.8" />
        <material name="block_mat" specular="0" shininess="0.5" reflectance="0" rgba="1 0.2 0.2 1" />
        <material name="robot0:geomMat" shininess="0.03" specular="0.4" />
        <material name="robot0:gripper_finger_mat" shininess="0.03" specular="0.4" reflectance="0" />
        <material name="robot0:gripper_mat" shininess="0.03" specular="0.4" reflectance="0" />
        <material name="robot0:base_mat" shininess="0.03" specular="0.4" reflectance="0" />
        <material name="grid_mat" texture="grid" texrepeat="8 8" reflectance="0.2" />
        <mesh name="base_link" file="robot/visual/base_link.stl" />
        <mesh name="link_1" file="robot/visual/link_1.stl" />
        <mesh name="link_2" file="robot/visual/link_2.stl" />
        <mesh name="link_3" file="robot/visual/link_3.stl" />
        <mesh name="link_4" file="robot/visual/link_4.stl" />
        <mesh name="link_5" file="robot/visual/link_5.stl" />
        <mesh name="link_6" file="robot/visual/link_6.stl" />
        <mesh name="pusher_link" file="robot/visual/pusher_link.stl" />
    </asset>
    <default>
        <default class="grab">
            <joint limited="false" margin="0.01" armature="0.001" damping="0" frictionloss="0.001" />
            <geom type="mesh" rgba=".93 .99 .97 1.0" />
            <site size="0.005 0 0" rgba="0.4 0.9 0.4 1" />
            <default class="object_col">
                <geom type="mesh" density="1250" contype="1" conaffinity="1" friction="1 0.5 0.01" margin="0.0005" condim="4" rgba=".3 .4 .5 1" group="3" />
            </default>
        </default>
    </default>
    <worldbody>
        <geom name="floor" size="5 5 5" type="plane" material="grid_mat" rgba="0.16 0.18 0.20 1" />
        <body pos="0.75 0 0" name="table0">
            <geom size="1 0.5 0.05" type="box" name="table" mass="2000" material="table_mat" friction="0 0 0" rgba="0.57 0.75 0.83 0.8" />
            <site name="site:table" pos="0 0 0" size="0.02 0.02 0.02" type="box" rgba="1 1 0 0" />
        </body>
        <body name="base_link" pos="0 0 0.035">
            <inertial pos="-0.0036 0 0.0014" quat="0.7605 -0.0133 -0.0061 0.6491" mass="70.1294" diaginertia="1.2869 1.2236 0.9868" />
            <geom type="mesh" mesh="base_link" name="robot0:base_link" rgba="1 0.43 0 1" contype="0" conaffinity="0" />
            <body name="link_1" pos="0 0 0" gravcomp="1">
                <joint name="joint_1" type="hinge" axis="0 0 1" range="-2.87979 2.87979" limited="true" damping="0.1" frictionloss="0.01" />
                <inertial pos="0.0006 -0.0004 0.2263" quat="0.8016 -0.0156 -0.0077 0.5977" mass="3.6488" diaginertia="0.0159 0.0157 0.0125" />
                <geom type="mesh" mesh="link_1" name="robot0:link_1" rgba="1 0.43 0 1" contype="0" conaffinity="0" />
                <body name="link_2" pos="0 0 0.29" gravcomp="1">
                    <joint name="joint_2" type="hinge" axis="0 1 0" range="-1.91986 1.91986" limited="true" damping="0.1" frictionloss="0.01" />
                    <inertial pos="0.0005 -0.0047 0.1061" quat="0.999978 0.00659 0.00036 -0.00049" mass="6.1585" diaginertia="0.072 0.054 0.027" />
                    <geom type="mesh" mesh="link_2" name="robot0:link_2" rgba="1 0.43 0 1" contype="0" conaffinity="0" />
                    <body name="link_3" pos="0 0 0.27" gravcomp="1">
                        <joint name="joint_3" type="hinge" axis="0 1 0" range="-1.22173 1.91986" limited="true" damping="0.1" frictionloss="0.01" />
                        <inertial pos="0.0349 0.0006 0.0609" quat="0.5408 0.4564 0.4341 0.5574" mass="2.7659" diaginertia="0.0161 0.0135 0.0062" />
                        <geom type="mesh" mesh="link_3" name="robot0:link_3" rgba="1 0.43 0 1" contype="0" conaffinity="0" />
                        <body name="link_4" pos="0 0 0.07" gravcomp="1">
                            <joint name="joint_4" type="hinge" axis="1 0 0" range="-2.79252 2.79252" limited="true" damping="0.1" frictionloss="0.01" />
                            <inertial pos="0.2331 0.0001 0.0016" quat="-0.005 0.716 -0.014 0.698" mass="1.5279" diaginertia="0.0053 0.0039 0.0028" />
                            <geom type="mesh" mesh="link_4" name="robot0:link_4" rgba="1 0.43 0 1" contype="0" conaffinity="0" />
                            <body name="link_5" pos="0.302 0 0" gravcomp="1">
                                <joint name="joint_5" type="hinge" axis="0 1 0" range="-2.0944 2.0944" limited="true" damping="0.1" frictionloss="0.01" />
                                <inertial pos="0.0067 0.0002 0.00004" quat="0.4995 0.4994 0.5002 0.5009" mass="0.4420" diaginertia="0.00068 0.00063 0.00028" />
                                <geom type="mesh" mesh="link_5" name="robot0:link_5" rgba="1 0.43 0 1" contype="0" conaffinity="0" />
                                <body name="link_6" pos="0.072 0 0" gravcomp="1">
                                    <joint name="joint_6" type="hinge" axis="1 0 0" range="-3.142 3.142" limited="true" damping="0.1" frictionloss="0.01" />
                                    <inertial pos="-0.0065 0.0002 0" quat="0.7063 0.7079 -0.0015 -0.0016" mass="0.0139" diaginertia="2.66e-6 1.52e-6 1.48e-6" />
                                    <geom type="mesh" mesh="link_6" name="robot0:link_6" rgba="0 0 0 1" contype="0" conaffinity="0" />
                                    <site name="site:tool0" pos="0 0 0" euler="0 0 0" size="0.01" />
                                    <body name="ft_and_adapter_link" pos="0.041125 0 0" gravcomp="1">
                                        <geom type="cylinder" size="0.0375 0.041125" euler="0 1.5708 0" rgba="0.5 0.5 0.5 1" mass="0.0" />
                                        <site name="site:sensor" pos="0.041125 0 0" euler="0 1.5708 1.5708" size="0.01" rgba="1 1 1 1" />
                                        <body name="pusher_link" pos="0.041125 0 0" euler="0 0 0" gravcomp="1">
                                            <geom name="push_rod" type="mesh" mass="0.064" euler="0 1.5708 0" mesh="pusher_link" material="robot0:gripper_mat" contype="0" conaffinity="0" rgba="0.12 0.12 0.12 1" />
                                            <geom name="push_ball_col" type="sphere" pos="0.09675 0 0" size="0.01325" friction="1.5 0.02 0.001" condim="4" mass="0.0" />
                                            <site name="site:ball_center" pos="0.09675 0 0" euler="0 0 0" size="0.01" rgba="1 1 1 1" />
                                            <site name="site:fingertip" pos="0.11 0 0" euler="0 0 0" size="0.01" rgba="1 1 1 1" />
                                        </body>
                                    </body>
                                </body>
                            </body>
                        </body>
                    </body>
                </body>
            </body>
        </body>
        <body name="payload" pos="0.58 0.08 0.2">
            <joint type="free" damping="0.01" />
            <inertial mass="0.663" pos="0 0 -0.01219" diaginertia="0.006083536 0.006083536 0.00185977" />
            <geom name="payload" type="box" size="0.05 0.05 0.15" material="block_mat" friction="0.1 0.1 0.0001" solref="0.0001 1.0" rgba="1 0 0 1" />
            <site name="site:payload" pos="0 0 0" size="0.02 0.02 0.02" type="box" rgba="1 1 1 0" />
            <site name="site:obj_frame" pos="-0.05 0.0 -0.15" size="0.02 0.02 0.02" type="box" rgba="1 1 1 1" />
        </body>
        <light directional="true" ambient="0.2 0.2 0.2" diffuse="0.8 0.8 0.8" specular="0.3 0.3 0.3" castshadow="false" pos="0 0 4" dir="0 0 -1" name="light0" />
    </worldbody>
</mujoco>